Workbook

Sheet Overview
A1: WORKLEDGER — Global Project Dashboard
A2: Owner: ACI (Remy Ruozzi) | Phase 1 MVP | 12 Weeks | Target: 10 Freelancers, 20 Jobs
A4: Department | B4: Owner | C4: Progress | D4: Tasks Done | E4: Tasks Total | F4: % Complete | G4: Risk Level | H4: Notes
A5: CODE DEV | B5: Claude + Remy | C5: =D5/E5 -> 0.52380952 | D5: 33 | E5: 63 | F5: =D5/E5 -> 0.52380952 | G5: Medium | H5: Sprint 1-4 done, Sprint 5 85%, Admin system built
A6: STRATEGY | B6: Remy + Claude | C6: =D6/E6 -> 0.66666667 | D6: 10 | E6: 15 | F6: =D6/E6 -> 0.66666667 | G6: Low | H6: Business model + MCC taxonomy finalized
A7: DESIGN | B7: Remy + Claude | C7: =D7/E7 -> 0.47058824 | D7: 8 | E7: 17 | F7: =D7/E7 -> 0.47058824 | G7: Medium | H7: Dark theme done, MCC design spec done, arch visualizations done
A8: MARKETING | B8: Remy | C8: =F8 -> 0 | D8: =Marketing!H2 -> 0 | E8: =Marketing!I2 -> 10 | F8: =IF(E8>0,D8/E8,0) -> 0 | G8: Low | H8: Deferred to post-MVP polish
A9: SECURITY | B9: Claude + Remy | C9: =F9 -> 0.33333333 | D9: =Security!H2 -> 5 | E9: =Security!I2 -> 15 | F9: =IF(E9>0,D9/E9,0) -> 0.33333333 | G9: High | H9: Key mgmt done, admin auth done, user middleware pending
A10: LEGAL | B10: Remy | C10: =F10 -> 0 | D10: =Legal!H2 -> 0 | E10: =Legal!I2 -> 12 | F10: =IF(E10>0,D10/E10,0) -> 0 | G10: Medium | H10: AUSTRAC research started, structure TBD
A12: OVERALL PROJECT | D12: =D5+D6+D7+D8+D9+D10 -> 56 | E12: =E5+E6+E7+E8+E9+E10 -> 132 | F12: =D12/E12 -> 0.42424242
A14: Sprint Timeline
A15: Sprint | B15: Weeks | C15: Focus | D15: Status | E15: Progress | F15: Key Deliverable | G15: Blockers | H15: Notes
A16: Sprint 1 | B16: 1-2 | C16: Foundation | D16: DONE | E16: 100% | F16: Dev env + XRPL testnet + DB | G16: - | H16: All complete
A17: Sprint 2 | B17: 3-4 | C17: Auth & Wallet | D17: IN PROGRESS | E17: 80% | F17: Registration, wallet, Xaman | G17: Redirect bug | H17: Xaman auth parked, Google OAuth done
A18: Sprint 3 | B18: 5-6 | C18: Contracts & Escrow | D18: IN PROGRESS | E18: 90% | F18: Fixed-price + escrow flow | G18: - | H18: Contracts + escrow + negotiation done, detail page WIP
A19: Sprint 4 | B19: 7-8 | C19: NFTs & Proof | D19: IN PROGRESS | E19: 45% | F19: PoW NFT minting + portfolio | G19: IPFS setup | H19: MCC taxonomy + design spec done, IPFS + auto-mint WIP
A20: Sprint 5 | B20: 9-10 | C20: Dashboard & Polish | D20: IN PROGRESS | E20: 80% | F20: Full dashboard + notifications | G20: - | H20: Dashboard done, admin system done, n8n done, notifications WIP
A21: Sprint 6 | B21: 11-12 | C21: Testing & Launch | D21: NOT STARTED | E21: 0% | F21: E2E testing + mainnet deploy | G21: - | H21: Depends on all above

Sheet Code Dev
A1: # | B1: Task | C1: Description | D1: Sprint | E1: Status | F1: Priority | G1: Assignee | H1: Files / Notes | I1: 33 | J1: 63
I2: =COUNTIF(E3:E100,"DONE") -> 34 | J2: =COUNTA(E3:E100) -> 63
A3: Sprint 1
A4: 1 | B4: Project scaffolding | C4: Next.js 14 + TS + Tailwind setup | D4: Sprint 1 | E4: DONE | F4: Critical | G4: Claude | H4: Complete
A5: 2 | B5: XRPL client manager | C5: Singleton connection with auto-reconnect | D5: Sprint 1 | E5: DONE | F5: Critical | G5: Claude | H5: src/lib/xrpl/client.ts
A6: 3 | B6: Wallet generation | C6: Keypair generation + trust lines | D6: Sprint 1 | E6: DONE | F6: Critical | G6: Claude | H6: src/lib/xrpl/wallet.ts
A7: 4 | B7: Escrow system | C7: Create/finish/cancel with crypto-conditions | D7: Sprint 1 | E7: DONE | F7: Critical | G7: Claude | H7: src/lib/xrpl/escrow.ts
A8: 5 | B8: NFT minting engine | C8: PoW, License, Access Pass minting | D8: Sprint 1 | E8: DONE | F8: High | G8: Claude | H8: src/lib/xrpl/nft.ts
A9: 6 | B9: Database schema | C9: 7 tables + RLS + indexes + triggers | D9: Sprint 1 | E9: DONE | F9: Critical | G9: Claude | H9: supabase/migrations/001
A10: 7 | B10: Supabase clients | C10: Browser + server client setup | D10: Sprint 1 | E10: DONE | F10: Critical | G10: Claude | H10: src/lib/supabase/
A11: 8 | B11: Type definitions | C11: All entity types | D11: Sprint 1 | E11: DONE | F11: High | G11: Claude | H11: src/types/index.ts
A12: 9 | B12: Zustand wallet store | C12: State mgmt with Xaman provider | D12: Sprint 1 | E12: DONE | F12: High | G12: Claude | H12: src/stores/wallet-store.ts
A13: Sprint 2
A14: 10 | B14: Landing page | C14: Hero, value props, CTA | D14: Sprint 2 | E14: DONE | F14: High | G14: Claude | H14: src/app/page.tsx
A15: 11 | B15: Login page | C15: Xaman + Google OAuth buttons | D15: Sprint 2 | E15: DONE | F15: Critical | G15: Claude | H15: src/app/(auth)/login/page.tsx
A16: 12 | B16: Google OAuth | C16: Supabase Auth with Google provider | D16: Sprint 2 | E16: DONE | F16: Critical | G16: Claude+Remy | H16: Vercel env configured
A17: 13 | B17: Xaman SDK wrapper | C17: QR modal, deep link, WebSocket | D17: Sprint 2 | E17: DONE | F17: Critical | G17: Claude | H17: src/lib/xaman/
A18: 14 | B18: Xaman auth flow | C18: SignIn verify + Supabase session | D18: Sprint 2 | E18: DONE | F18: Critical | G18: Claude | H18: src/app/api/auth/xaman/
A19: 15 | B19: Admin Supabase client | C19: Service role for user creation | D19: Sprint 2 | E19: DONE | F19: Critical | G19: Claude | H19: src/lib/supabase/admin.ts
A20: 16 | B20: Xaman redirect fix | C20: useEffect-based redirect after sign | D20: Sprint 2 | E20: PARKED | F20: Medium | G20: Claude | H20: Bug: redirect not firing consistently
A21: 17 | B21: Auth middleware | C21: Route protection for dashboard | D21: Sprint 2 | E21: IN PROGRESS | F21: High | G21: Claude | H21: Admin middleware done (withAdmin), user middleware pending
A22: 18 | B22: Wallet display page | C22: Balance card + currency toggle | D22: Sprint 2 | E22: NOT STARTED | F22: High | G22: Claude | H22: src/app/(dashboard)/wallet/
A23: 19 | B23: Transaction history | C23: Recent XRPL tx list | D23: Sprint 2 | E23: NOT STARTED | F23: Medium | G23: Claude | H23: TransactionList component
A24: Sprint 3
A25: 20 | B25: Contract creation form | C25: Fixed-price template form | D25: Sprint 3 | E25: DONE | F25: Critical | G25: Claude | H25: FixedPriceForm component
A26: 21 | B26: Contract generation engine | C26: Form input to XRPL params | D26: Sprint 3 | E26: DONE | F26: Critical | G26: Claude | H26: src/lib/contracts/generator.ts
A27: 22 | B27: Contract API routes | C27: CRUD endpoints | D27: Sprint 3 | E27: DONE | F27: High | G27: Claude | H27: src/app/api/contracts/
A28: 23 | B28: Milestone escrow API | C28: Fund/release with Xaman support | D28: Sprint 3 | E28: DONE | F28: Critical | G28: Claude | H28: milestones/[seq]/route.ts
A29: 24 | B29: Retainer contract | C29: Recurring escrow template | D29: Sprint 3 | E29: DONE | F29: High | G29: Claude | H29: retainer-escrow.ts
A30: 25 | B30: Escrow WebSocket listener | C30: Real-time funding confirmation | D30: Sprint 3 | E30: NOT STARTED | F30: High | G30: Claude | H30: src/lib/xrpl/listener.ts
A31: 26 | B31: Contract detail page | C31: Status, milestones, parties view | D31: Sprint 3 | E31: IN PROGRESS | F31: High | G31: Claude | H31: Contract detail view built in session 15-16
A32: 27 | B32: Platform fee deduction | C32: 2% on escrow release | D32: Sprint 3 | E32: IN PROGRESS | F32: Medium | G32: Claude | H32: 0.98% fee in release flow, fee_ledger table ready
A33: Sprint 4
A34: 28 | B34: IPFS/Pinata upload | C34: NFT metadata JSON to IPFS | D34: Sprint 4 | E34: NOT STARTED | F34: High | G34: Claude | H34: src/lib/ipfs/pinata.ts
A35: 29 | B35: Auto-mint on approval | C35: PoW NFT in escrow release flow | D35: Sprint 4 | E35: IN PROGRESS | F35: High | G35: Claude | H35: Mock mint in test mode, MCC-DESIGN.md spec complete
A36: 30 | B36: Deliverable hashing | C36: SHA-256 of uploaded files | D36: Sprint 4 | E36: NOT STARTED | F36: Medium | G36: Claude | H36: src/lib/utils/hash.ts
A37: 31 | B37: NFT portfolio page | C37: Grid view of all NFTs | D37: Sprint 4 | E37: IN PROGRESS | F37: High | G37: Claude | H37: MCCPortfolio + MCCCard spec in MCC-DESIGN.md
A38: 32 | B38: NFT taxonomy rename | C38: PoW->Work Credential, AP->Membership | D38: Sprint 4 | E38: DONE | F38: Medium | G38: Remy+Claude | H38: MCC: Work Credential (T1), License (T2), Access Pass (T3), Client Completion (T4)
A39: 33 | B39: Public profile page | C39: User profile + NFT portfolio | D39: Sprint 4 | E39: NOT STARTED | F39: Medium | G39: Claude | H39: profile/page.tsx
A40: 34 | B40: Reputation scoring | C40: On-chain avg rating + job count | D40: Sprint 4 | E40: NOT STARTED | F40: Medium | G40: Claude | H40: src/lib/reputation.ts
...

Sheet Strategy
A1: # | B1: Task | C1: Description | D1: Category | E1: Status | F1: Priority | G1: Notes | H1: 10 | I1: 15
H2: =COUNTIF(E3:E100,"DONE") -> 10 | I2: =COUNTA(E3:E100) -> 15
A3: 1 | B3: Business model definition | C3: Fee structure: 0.98% platform fee on escrow release | D3: Revenue | E3: DONE | F3: Critical | G3: Updated to 0.98% in session 13+
A4: 2 | B4: Target user personas | C4: Phase 1: Web3 freelancers, Phase 2: international $30-100K | D4: Market | E4: DONE | F4: High | G4: 3-phase growth plan documented
A5: 3 | B5: Competitive positioning | C5: Web2 comparison (Upwork, Fiverr, Deel, PayPal) | D5: Market | E5: DONE | F5: High | G5: PDF report generated
A6: 4 | B6: Growth strategy doc | C6: Market entry, pain points, advantages | D6: Market | E6: DONE | F6: High | G6: PDF report generated
A7: 5 | B7: NFT taxonomy design | C7: Work Credential / License / Membership naming | D7: Product | E7: DONE | F7: High | G7: MCC: 4 taxons defined in MCC-DESIGN.md
A8: 6 | B8: Smart contract taxonomy | C8: 10 contract types mapped to WorkLedger | D8: Product | E8: DONE | F8: Medium | G8: Fixed-price + milestone impl
A9: 7 | B9: Currency strategy | C9: RLUSD primary + GateHub fiat + XRP native | D9: Product | E9: DONE | F9: High | G9: 8 currencies configured
A10: 8 | B10: i18n priority list | C10: JP > ES > PT > FR > AR > ZH > RU | D10: Growth | E10: DONE | F10: Medium | G10: Japanese first market
A11: 9 | B11: Team scaling triggers | C11: 50u->CM, 100->Dispute, 200->Dev, 500->Legal | D11: Ops | E11: DONE | F11: Medium | G11: Documented in CLAUDE.md
A12: 10 | B12: UX philosophy | C12: Product power + ergonomics first, marketing later | D12: Product | E12: DONE | F12: High | G12: Remy's direction
A13: 11 | B13: Wallet as gateway | C13: Wallet is primary user entry point | D13: UX | E13: PLANNED | F13: High | G13: Design around wallet-first UX
A14: 12 | B14: Client vs freelancer modes | C14: Distinct color schemes per role | D14: UX | E14: PLANNED | F14: Medium | G14: Phase 2 feature
... A17: 15 | B17: Department AI workflow | C17: 6 depts with parallel AI agents | D17: Ops | E17: PLANNED | F17: Medium | G17: Needs Claude Max

Sheet Design
A1: # | B1: Task | C1: Description | D1: Category | E1: Status | F1: Priority | G1: Notes | H1: 8 | I1: 17
H2: =COUNTIF(E3:E100,"DONE") -> 7 | I2: =COUNTA(E3:E100) -> 17
A3: 1 | B3: Dark Web3 theme | C3: Dark background, brand purple, glow accents | D3: Theme | E3: DONE | F3: Critical | G3: globals.css + Tailwind config
A4: 2 | B4: Color system | C4: Brand purple #6C63FF + semantic colors | D4: Theme | E4: DONE | F4: High | G4: CSS custom properties
A5: 3 | B5: Dashboard wireframes | C5: Bento grid + command center concepts | D5: Layout | E5: DONE | F5: High | G5: docs/dashboard-wireframes.jsx
A6: 4 | B6: Login page design | C6: Xaman + Google CTA, dark card style | D6: Pages | E6: DONE | F6: High | G6: Deployed and working
A7: 5 | B7: Landing page design | C7: Hero, value props, CTA sections | D7: Pages | E7: DONE | F7: High | G7: Deployed
A8: 6 | B8: Component library | C8: Buttons, cards, forms, modals, badges | D8: Components | E8: IN PROGRESS | F8: High | G8: XamanSignModal done, more needed
A9: 7 | B9: Wallet UI design | C9: Balance cards, currency toggle, tx list | D9: Pages | E9: NOT STARTED | F9: High | G9: Wallet-first UX approach
A10: 8 | B10: Contract UI design | C10: Creation form, detail view, status flow | D10: Pages | E10: NOT STARTED | F10: High | G10: Template-based approach
A11: 9 | B11: NFT portfolio design | C11: Grid view, detail cards, metadata display | D11: Pages | E11: IN PROGRESS | F11: Medium | G11: MCC-DESIGN.md: full card anatomy, animations, typography, print/export
A12: 10 | B12: Sidebar/navigation design | C12: Responsive sidebar with role context | D12: Layout | E12: IN PROGRESS | F12: High | G12: Basic done, needs polish
A13: 11 | B13: Mobile responsive design | C13: Tablet + phone breakpoints | D13: Layout | E13: NOT STARTED | F13: Medium | G13: Tailwind responsive classes
A14: 12 | B14: Icon system | C14: Lucide React icons throughout | D14: Components | E14: IN PROGRESS | F14: Low | G14: Already using lucide-react
... A19: 17 | B19: MCC credential card design | C19: Federal certificate aesthetic: guilloche, seals, 4 taxon palettes | D19: Components | E19: DONE | F19: High | G19: MCC-DESIGN.md: MCCCard, MCCPortfolio, MCCPrintView specs

Sheet Marketing
A1: # | B1: Task | C1: Description | D1: Phase | E1: Status | F1: Priority | G1: Notes | H1: Done | I1: Total
H2: =COUNTIF(E3:E100,"DONE") -> 0 | I2: =COUNTA(E3:E100) -> 10
A3: 1 | B3: Brand identity | C3: Logo, color palette, typography guide | D3: Pre-launch | E3: NOT STARTED | F3: High | G3: Dark Web3 aesthetic defined
A4: 2 | B4: Landing page copy | C4: Hero text, value props, CTAs | D4: Pre-launch | E4: PLANNED | F4: Medium | G4: After product UX finalized
A5: 3 | B5: XRPL community outreach | C5: Engage XRPL devs and community | D5: Phase 1 | E5: PLANNED | F5: High | G5: First 10 users from here
A6: 4 | B6: Social media presence | C6: Twitter/X, LinkedIn profiles | D6: Phase 1 | E6: NOT STARTED | F6: Medium | G6: Consistent branding
A7: 5 | B7: Demo video | C7: 2-min product walkthrough | D7: Phase 1 | E7: NOT STARTED | F7: Medium | G7: After MVP stable
A8: 6 | B8: Freelancer testimonials | C8: Case studies from first users | D8: Phase 1 | E8: NOT STARTED | F8: Low | G8: After 10 users onboarded
A9: 7 | B9: Content strategy | C9: Blog posts on XRPL + freelancing | D9: Phase 2 | E9: NOT STARTED | F9: Low | G9: SEO + thought leadership
A10: 8 | B10: International launch (JP) | C10: Japanese localization + outreach | D10: Phase 2 | E10: NOT STARTED | F10: Medium | G10: First i18n market
A11: 9 | B11: Partnership outreach | C11: Creative agencies, photo studios | D11: Phase 2 | E11: NOT STARTED | F11: Medium | G11: Remy's network
A12: 10 | B12: Referral program design | C12: Incentive structure for growth | D12: Phase 2 | E12: NOT STARTED | F12: Low | G12: After product-market fit

Sheet Security
A1: # | B1: Task | C1: Description | D1: Category | E1: Status | F1: Priority | G1: Notes | H1: 5 | I1: 15
H2: =COUNTIF(E3:E100,"DONE") -> 5 | I2: =COUNTA(E3:E100) -> 15
A3: 1 | B3: Encrypted seed storage | C3: crypto.createCipheriv for wallet seeds | D3: Key Mgmt | E3: DONE | F3: Critical | G3: In auth register flow
A4: 2 | B4: Service role isolation | C4: Admin client separated from browser client | D4: Auth | E4: DONE | F4: Critical | G4: src/lib/supabase/admin.ts
A5: 3 | B5: RLS policies | C5: Row-level security on all tables | D5: Database | E5: DONE | F5: Critical | G5: In migration SQL
A6: 4 | B6: Env var management | C6: Secrets in .env.local, not in code | D6: Config | E6: DONE | F6: Critical | G6: Vercel env vars configured
A7: 5 | B7: Multi-sign wallet (2-of-3) | C7: User + platform + recovery key | D7: Key Mgmt | E7: NOT STARTED | F7: Critical | G7: Sprint 2+ planned
A8: 6 | B8: API route authorization | C8: Verify auth on all protected endpoints | D8: Auth | E8: IN PROGRESS | F8: Critical | G8: Admin withAdmin() middleware done, user routes pending
A9: 7 | B9: Input validation (Zod) | C9: Validate all API inputs with Zod | D9: API | E9: NOT STARTED | F9: High | G9: At API boundaries
A10: 8 | B10: Rate limiting | C10: Prevent API abuse | D10: API | E10: NOT STARTED | F10: High | G10: Vercel Edge or custom
A11: 9 | B11: XRPL tx verification | C11: Verify on-chain before DB update | D11: Blockchain | E11: NOT STARTED | F11: Critical | G11: Trust but verify pattern
A12: 10 | B12: Escrow condition security | C12: Crypto-conditions properly generated | D12: Blockchain | E12: DONE | F12: Critical | G12: five-bells-condition lib
A13: 11 | B13: XSS prevention | C13: Sanitize all user inputs in UI | D13: Frontend | E13: NOT STARTED | F13: High | G13: React auto-escaping helps
A14: 12 | B14: CSRF protection | C14: Token-based request validation | D14: API | E14: NOT STARTED | F14: Medium | G14: Next.js built-in + custom
... A17: 15 | B17: Incident response plan | C17: What to do if breach detected | D17: Ops | E17: NOT STARTED | F17: Medium | G17: Document before mainnet

Sheet Legal
A1: # | B1: Task | C1: Description | D1: Category | E1: Status | F1: Priority | G1: Notes | H1: 0 | I1: 12
H2: =COUNTIF(E3:E100,"DONE") -> 0 | I2: =COUNTA(E3:E100) -> 12
A3: 1 | B3: Company structure decision | C3: Sole trader vs Pty Ltd vs offshore | D3: Entity | E3: NOT STARTED | F3: High | G3: Australia or Singapore?
A4: 2 | B4: Terms of Service | C4: Platform usage terms | D4: Docs | E4: NOT STARTED | F4: Critical | G4: Before mainnet launch
A5: 3 | B5: Privacy Policy | C5: GDPR + Australian Privacy Act compliant | D5: Docs | E5: NOT STARTED | F5: Critical | G5: Before mainnet launch
A6: 4 | B6: KYC requirements analysis | C6: When/if KYC needed for XRPL escrow | D6: Compliance | E6: NOT STARTED | F6: High | G6: Deferred for beta
A7: 5 | B7: AML/CTF assessment | C7: Anti-money laundering obligations | D7: Compliance | E7: IN PROGRESS | F7: High | G7: AUSTRAC enrollment research done (docs/AUSTRAC.md, AUSTRAC-ENROLLMENT.md)
A8: 6 | B8: RLUSD regulatory status | C8: NYDFS regulated stablecoin implications | D8: Compliance | E8: PLANNED | F8: Medium | G8: Research needed
A9: 7 | B9: OFAC sanctions compliance | C9: Blocked countries/addresses list | D9: Compliance | E9: NOT STARTED | F9: High | G9: Critical for mainnet
A10: 8 | B10: Escrow legal framework | C10: Smart contract as legal agreement? | D10: Legal | E10: NOT STARTED | F10: Medium | G10: Depends on jurisdiction
A11: 9 | B11: NFT IP rights | C11: Work Credential ownership + licensing | D11: IP | E11: NOT STARTED | F11: Medium | G11: Part of taxonomy design
A12: 10 | B12: Dispute resolution policy | C12: Arbitration flow + fee structure | D12: Policy | E12: PLANNED | F12: Medium | G12: 5% from losing party
A13: 11 | B13: Tax reporting obligations | C13: GST/VAT on platform fees | D13: Tax | E13: NOT STARTED | F13: Medium | G13: Accounting setup needed
A14: 12 | B14: Open source licensing | C14: MIT or proprietary for codebase | D14: IP | E14: NOT STARTED | F14: Low | G14: Decide before public repo
